<?xml version="1.0"?>
<!-- 机器人的URDF描述文件 -->

<robot name="robot">

  <!-- 机器人的底盘 -->
  <link name="base_footprint"/>

  <!-- 底盘和基本连接处的关节 -->
  <joint name="base_joint" type="fixed">
    <parent link="base_footprint"/>
    <child link="base_link"/>
    <origin xyz="0.0 0.0 0.076" rpy="0 0 0"/>
  </joint>

  <!-- 机器人的主体链接 -->
  <link name="base_link">
    <!-- 可视化描述 -->
    <visual>
      <origin xyz="0 0 0.0" rpy="0 0 0"/>
      <geometry>
        <cylinder length="0.12" radius="0.10"/>
      </geometry>
      <material name="blue">
        <color rgba="0.1 0.1 1.0 0.5" /> <!-- 蓝色半透明材质 -->
      </material>
    </visual>
    <!-- 碰撞检测描述 -->
    <collision>
      <origin xyz="0 0 0.0" rpy="0 0 0"/>
      <geometry>
        <cylinder length="0.12" radius="0.10"/>
      </geometry>
      <material name="blue">
        <color rgba="0.1 0.1 1.0 0.5" /> <!-- 蓝色半透明材质 -->
      </material>
    </collision>
    <!-- 惯性描述 -->
    <inertial>
      <mass value="0.2"/> <!-- 质量 -->
      <inertia ixx="0.0122666" ixy="0" ixz="0" iyy="0.0122666" iyz="0" izz="0.02"/> <!-- 转动惯量 -->
    </inertial>
  </link>
    
  <!-- 激光传感器链接 -->
  <link name="liser_link">
    <!-- 可视化描述 -->
    <visual>
      <origin xyz="0 0 0" rpy="0 0 0"/>
      <geometry>
        <cylinder length="0.02" radius="0.02"/>
      </geometry>
      <material name="black">
        <color rgba="0.0 0.0 0.0 0.5" /> <!-- 黑色半透明材质 -->
      </material>
    </visual>
    <!-- 碰撞检测描述 -->
    <collision>
      <origin xyz="0 0 0" rpy="0 0 0"/>
      <geometry>
        <cylinder length="0.02" radius="0.02"/>
      </geometry>
      <material name="black">
        <color rgba="0.0 0.0 0.0 0.5" /> <!-- 黑色半透明材质 -->
      </material>
    </collision>
    <!-- 惯性描述 -->
    <inertial>
      <mass value="0.1"/> <!-- 质量 -->
      <inertia ixx="0.000190416666667" ixy="0" ixz="0" iyy="0.0001904" iyz="0" izz="0.00036"/> <!-- 转动惯量 -->
    </inertial>
  </link>
  
  <!-- 激光传感器和主体连接处的关节 -->
  <joint name="laser_joint" type="fixed">
    <parent link="base_link" />
    <child link="liser_link" />
    <origin xyz="0 0 0.075" /> <!-- 相对于base_link的位置 -->
  </joint>

  <!-- IMU链接 -->
  <link name="imu_link">
    <!-- 可视化描述 -->
    <visual>
      <origin xyz="0 0 0.0" rpy="0 0 0"/>
      <geometry>
        <box size="0.02 0.02 0.02"/>
      </geometry>
    </visual>
    <!-- 碰撞检测描述 -->
    <collision>
      <origin xyz="0 0 0.0" rpy="0 0 0"/>
      <geometry>
        <box size="0.02 0.02 0.02"/>
      </geometry>
    </collision>
    <!-- 惯性描述 -->
    <inertial>
      <mass value="0.1"/> <!-- 质量 -->
      <inertia ixx="0.000190416666667" ixy="0" ixz="0" iyy="0.0001904" iyz="0" izz="0.00036"/> <!-- 转动惯量 -->
    </inertial>
  </link>

  <!-- IMU和主体连接处的关节 -->
  <joint name="imu_joint" type="fixed">
    <parent link="base_link" />
    <child link="imu_link" />
    <origin xyz="0 0 0.02" /> <!-- 相对于base_link的位置 -->
  </joint>

  <!-- 左轮链接 -->
  <link name="left_wheel_link">
    <!-- 可视化描述 -->
    <visual>
      <origin xyz="0 0 0" rpy="1.57079 0 0"/>
      <geometry>
        <cylinder length="0.04" radius="0.032"/>
      </geometry>
      <material name="black">
        <color rgba="0.0 0.0 0.0 0.5" /> <!-- 黑色半透明材质 -->
      </material>
    </visual>
    <!-- 碰撞检测描述 -->
    <collision>
      <origin xyz="0 0 0" rpy="1.57079 0 0"/>
      <geometry>
        <cylinder length="0.04" radius="0.032"/>
      </geometry>
      <material name="black">
        <color rgba="0.0 0.0 0.0 0.5" /> <!-- 黑色半透明材质 -->
      </material>
    </collision>
    <!-- 惯性描述 -->
    <inertial>
      <mass value="0.2"/> <!-- 质量 -->
      <inertia ixx="0.000190416666667" ixy="0" ixz="0" iyy="0.0001904" iyz="0" izz="0.00036"/> <!-- 转动惯量 -->
    </inertial>
  </link>
    
  <!-- 右轮链接 -->
  <link name="right_wheel_link">
    <!-- 可视化描述 -->
    <visual>
      <origin xyz="0 0 0" rpy="1.57079 0 0"/>
      <geometry>
        <cylinder length="0.04" radius="0.032"/>
      </geometry>
      <material name="black">
        <color rgba="0.0 0.0 0.0 0.5" /> <!-- 黑色半透明材质 -->
      </material>
    </visual>
    <!-- 碰撞检测描述 -->
    <collision>
      <origin xyz="0 0 0" rpy="1.57079 0 0"/>
      <geometry>
        <cylinder length="0.04" radius="0.032"/>
      </geometry>
      <material name="black">
        <color rgba="0.0 0.0 0.0 0.5" /> <!-- 黑色半透明材质 -->
      </material>
    </collision>
    <!-- 惯性描述 -->
    <inertial>
      <mass value="0.2"/> <!-- 质量 -->
      <inertia ixx="0.000190416666667" ixy="0" ixz="0" iyy="0.0001904" iyz="0" izz="0.00036"/> <!-- 转动惯量 -->
    </inertial>
  </link>
    
  <!-- 左轮关节 -->
  <joint name="left_wheel_joint" type="continuous">
    <parent link="base_link" />
    <child link="left_wheel_link" />
    <origin xyz="-0.02 0.10 -0.06" /> <!-- 相对于base_link的位置 -->
    <axis xyz="0 1 0" /> <!-- 转动轴方向 -->
  </joint>

  <!-- 右轮关节 -->
  <joint name="right_wheel_joint" type="continuous">
    <parent link="base_link" />
    <child link="right_wheel_link" />
    <origin xyz="-0.02 -0.10 -0.06" /> <!-- 相对于base_link的位置 -->
    <axis xyz="0 1 0" /> <!-- 转动轴方向 -->
  </joint>

  <!-- 转向轮链接 -->
  <link name="caster_link">
    <!-- 可视化描述 -->
    <visual>
      <origin xyz="0 0 0" rpy="1.57079 0 0"/>
      <geometry>
        <sphere radius="0.016"/>
      </geometry>
      <material name="black">
        <color rgba="0.0 0.0 0.0 0.5" /> <!-- 黑色半透明材质 -->
      </material>
    </visual>
    <!-- 碰撞检测描述 -->
    <collision>
      <origin xyz="0 0 0" rpy="1.57079 0 0"/>
      <geometry>
        <sphere radius="0.016"/>
      </geometry>
      <material name="black">
        <color rgba="0.0 0.0 0.0 0.5" /> <!-- 黑色半透明材质 -->
      </material>
    </collision>
    <!-- 惯性描述 -->
    <inertial>
      <mass value="0.02"/> <!-- 质量 -->
      <inertia ixx="0.000190416666667" ixy="0" ixz="0" iyy="0.0001904" iyz="0" izz="0.00036"/> <!-- 转动惯量 -->
    </inertial>
  </link>
    
  <!-- 转向轮关节 -->
  <joint name="caster_joint" type="fixed">
    <parent link="base_link" />
    <child link="caster_link" />
    <origin xyz="0.06 0.0 -0.076" /> <!-- 相对于base_link的位置 -->
    <axis xyz="0 1 0" /> <!-- 转动轴方向 -->
  </joint>

  
  <!-- 深度相机链接 -->
  <link name="depth_camera_link">
    <!-- 可视化描述 -->
    <visual>
      <origin xyz="0 0 0" rpy="0 0 0"/>
      <geometry>
        <box size="0.05 0.1 0.03"/> <!-- 相机外壳的形状 -->
      </geometry>
      <material name="gray">
        <color rgba="0.5 0.5 0.5 0.8" /> <!-- 灰色半透明材质 -->
      </material>
    </visual>
    <!-- 碰撞检测描述 -->
    <collision>
      <origin xyz="0 0 0" rpy="0 0 0"/>
      <geometry>
        <box size="0.05 0.1 0.03"/> <!-- 相机外壳的形状 -->
      </geometry>
    </collision>
    <!-- 惯性描述 -->
    <inertial>
      <mass value="0.1"/> <!-- 质量 -->
      <inertia ixx="0.0001" ixy="0" ixz="0" iyy="0.0001" iyz="0" izz="0.0001"/> <!-- 转动惯量 -->
    </inertial>
  </link>

  <!-- 深度相机与主体的关节 -->
  <joint name="depth_camera_joint" type="fixed">
    <parent link="base_link"/>
    <child link="depth_camera_link"/>
    <origin xyz="0.1 0 0.6" rpy="0 0 0"/> <!-- 相对于base_link的位置，调整位置以适应实际模型 -->
  </joint>

  <!-- 在RVIZ中显示点云位姿错误，此处加入一个空连杆和空关节，用于调整点云tf位姿 -->
  <link name="link_camera_fake"></link>
  <joint name="joint_camera_fake" type="fixed">
    <origin xyz="0 0 0" rpy="-1.5708 0 -1.5708"/>
    <parent link="depth_camera_link"/>
    <child link="link_camera_fake"/>
  </joint>


  <!-- Gazebo模拟 -->
  <gazebo reference="caster_link">
    <material>Gazebo/Black</material>
    <mu1 value="0.0"/> <!-- 摩擦系数 -->
    <mu2 value="0.0"/>
    <kp value="1000000.0" /> <!-- 接触点刚度 -->
    <kd value="10.0" /> <!-- 接触点阻尼 -->
  </gazebo>

  <!-- 差分驱动插件 -->
  <gazebo>
    <plugin name='diff_drive' filename='libgazebo_ros_diff_drive.so'>
      <ros>
        <namespace>/</namespace>
        <remapping>cmd_vel:=cmd_vel</remapping>
        <remapping>odom:=odom</remapping>
      </ros>
      <update_rate>20</update_rate> <!-- 更新频率 -->
      <!-- 轮子描述 -->
      <left_joint>left_wheel_joint</left_joint>
      <right_joint>right_wheel_joint</right_joint>
      <!-- 运动学参数 -->
      <wheel_separation>0.2</wheel_separation> <!-- 轮子间距 -->
      <wheel_diameter>0.065</wheel_diameter> <!-- 轮子直径 -->
      <!-- 限制 -->
      <max_wheel_torque>20</max_wheel_torque> <!-- 最大轮子扭矩 -->
      <max_wheel_acceleration>1.0</max_wheel_acceleration> <!-- 最大轮子加速度 -->
      <!-- 输出 -->
      <publish_odom>true</publish_odom> <!-- 发布odom话题 -->
      <publish_odom_tf>true</publish_odom_tf> <!-- 发布odom TF -->
      <publish_wheel_tf>true</publish_wheel_tf> <!-- 发布轮子TF -->
      <odometry_frame>odom</odometry_frame> <!-- 里程计TF坐标系 -->
      <robot_base_frame>base_footprint</robot_base_frame> <!-- 机器人基座坐标系 -->
    </plugin>
  </gazebo>

  <!-- IMU传感器 -->
  <gazebo reference="imu_link">
    <sensor name="imu_sensor" type="imu">
      <plugin filename="libgazebo_ros_imu_sensor.so" name="imu_plugin">
        <ros>
          <namespace>/</namespace>
          <remapping>~/out:=imu</remapping>
        </ros>
        <initial_orientation_as_reference>false</initial_orientation_as_reference> <!-- 初始方向作为参考 -->
      </plugin>
      <always_on>true</always_on> <!-- 始终开启 -->
      <update_rate>20</update_rate> <!-- 更新频率 -->
      <visualize>true</visualize> <!-- 可视化 -->
      <!-- IMU传感器误差模型 -->
      <imu>
        <angular_velocity>
          <x>
            <noise type="gaussian">
              <mean>0.0</mean>
              <stddev>2e-4</stddev>
              <bias_mean>0.0000075</bias_mean>
              <bias_stddev>0.0000008</bias_stddev>
            </noise>
          </x>
          <y>
            <noise type="gaussian">
              <mean>0.0</mean>
              <stddev>2e-4</stddev>
              <bias_mean>0.0000075</bias_mean>
              <bias_stddev>0.0000008</bias_stddev>
            </noise>
          </y>
          <z>
            <noise type="gaussian">
              <mean>0.0</mean>
              <stddev>2e-4</stddev>
              <bias_mean>0.0000075</bias_mean>
              <bias_stddev>0.0000008</bias_stddev>
            </noise>
          </z>
        </angular_velocity>
        <linear_acceleration>
          <x>
            <noise type="gaussian">
              <mean>0.0</mean>
              <stddev>1.7e-2</stddev>
              <bias_mean>0.1</bias_mean>
              <bias_stddev>0.001</bias_stddev>
            </noise>
          </x>
          <y>
            <noise type="gaussian">
              <mean>0.0</mean>
              <stddev>1.7e-2</stddev>
              <bias_mean>0.1</bias_mean>
              <bias_stddev>0.001</bias_stddev>
            </noise>
          </y>
          <z>
            <noise type="gaussian">
              <mean>0.0</mean>
              <stddev>1.7e-2</stddev>
              <bias_mean>0.1</bias_mean>
              <bias_stddev>0.001</bias_stddev>
            </noise>
          </z>
        </linear_acceleration>
      </imu>
    </sensor>
  </gazebo>

  <!-- 激光传感器 -->
  <gazebo reference="liser_link">
    <sensor name="laser_sensor" type="ray">
      <always_on>false</always_on> <!-- 始终开启 -->
      <visualize>false</visualize> <!-- 可视化 -->
      <update_rate>10.0</update_rate> <!-- 更新频率 -->
      <pose>0 0 0.075 0 0 0</pose> <!-- 位姿 -->
      <!-- 射线描述 -->
      <ray>
        <scan>
          <horizontal>
            <samples>180</samples> <!-- 采样点数 -->
            <resolution>1.000000</resolution> <!-- 分辨率 -->
            <min_angle>-1.570000</min_angle> <!-- 最小角度 -->
            <max_angle>1.570000</max_angle> <!-- 最大角度 -->
          </horizontal>
        </scan>
        <range>
          <min>0.120000</min> <!-- 最小检测距离 -->
          <max>10.0</max> <!-- 最大检测距离 -->
          <resolution>0.015000</resolution> <!-- 分辨率 -->
        </range>
        <noise>
          <type>gaussian</type> <!-- 噪声类型 -->
          <mean>0.0</mean> <!-- 均值 -->
          <stddev>0.01</stddev> <!-- 标准差 -->
        </noise>
      </ray>

      <!-- 激光传感器ROS插件 -->
      <plugin name="laserscan" filename="libgazebo_ros_ray_sensor.so">
        <ros>
          <remapping>~/out:=scan</remapping>
        </ros>
        <output_type>sensor_msgs/LaserScan</output_type> <!-- 输出消息类型 -->
        <frame_name>liser_link</frame_name> <!-- 框架名 -->
      </plugin>
    </sensor>
  </gazebo>

  
  <gazebo reference="depth_camera_link">
      <sensor type="depth" name="my_sensor">
          <!-- 设置传感器始终开启 -->
          <always_on>true</always_on>
          <!-- 设置传感器的更新频率，单位为Hz -->
          <update_rate>15.0</update_rate>
          
          <!-- 定义相机的参数 -->
          <camera name="my_camera">
              <!-- 图像分辨率设置 -->
              <image>
                  <width>640</width>  <!-- 图像的宽度，像素单位 -->
                  <height>480</height> <!-- 图像的高度，像素单位 -->
              </image>
              
              <!-- 相机的裁剪平面，控制相机的检测范围 -->
              <clip>
                  <near>0.1</near>  <!-- 相机最近可以检测到的距离，单位为米 -->
                  <far>6</far>      <!-- 相机最远可以检测到的距离，单位为米 -->
              </clip>
              
              <!-- 相机的失真参数设置，用于校正镜头的几何失真 -->
              <distortion>
                  <k1>0.0</k1>  <!-- 径向失真参数k1 -->
                  <k2>0.0</k2>  <!-- 径向失真参数k2 -->
                  <k3>0.0</k3>  <!-- 径向失真参数k3 -->
                  <p1>0.0</p1>  <!-- 切向失真参数p1 -->
                  <p2>0.0</p2>  <!-- 切向失真参数p2 -->
                  <center>0.0 0.0</center>  <!-- 失真校正的中心点坐标 -->
              </distortion>
          </camera>

          <!-- 插件部分，用于将深度相机数据发布到ROS系统中 -->
          <plugin name="plugin_name_whatever" filename="libgazebo_ros_camera.so">
              <!-- ROS相关配置 -->
              <ros>
                  <namespace></namespace> <!-- ROS命名空间，留空表示使用全局命名空间 -->
                  <!-- 话题重映射，将Gazebo中的相机话题映射到ROS中的话题 -->
                  <remapping>~/image_raw:=/camera/rgb/image_raw</remapping> <!-- 原始RGB图像数据 -->
                  <remapping>~/image_rect:=/camera/rgb/image_rect_color</remapping> <!-- 校正后的RGB图像数据 -->
                  <remapping>~/image_depth:=/camera/depth/image_raw</remapping> <!-- 原始深度图像数据 -->
                  <remapping>~/depth/disparity:=/camera/depth/disparity</remapping> <!-- 深度图像的视差数据 -->
                  <remapping>~/camera_info:=/camera/rgb/camera_info</remapping> <!-- RGB相机内参信息 -->
                  <remapping>~/depth/camera_info:=/camera/depth/camera_info</remapping> <!-- 深度相机内参信息 -->
                  <remapping>~/points:=/camera/depth/points</remapping> <!-- 点云数据 -->
                  <remapping>~/camera_trigger:=/camera/trigger</remapping> <!-- 相机触发器数据 -->
                  <remapping>~/events:=/camera/events</remapping> <!-- 相机事件数据 -->
                  <remapping>~/diagnostics:=/camera/diagnostics</remapping> <!-- 相机诊断数据 -->
              </ros>

              <!-- 指定相机的框架名，这里使用了一个虚拟的框架link_camera_fake，以纠正深度相机在RViz中的显示方向 -->
              <frame_name>link_camera_fake</frame_name>
              <!-- 用于调整双目相机之间的基线距离，这里设置为0.07米 -->
              <hack_baseline>0.07</hack_baseline>
              <!-- 指定相机可以检测的最小深度值，单位为米 -->
              <min_depth>0.001</min_depth>
          </plugin>
      </sensor>
  </gazebo>


</robot>
